[2025-03-03T02:15:28.882+0000] {local_task_job_runner.py:123} INFO - ::group::Pre task execution logs
[2025-03-03T02:15:28.912+0000] {taskinstance.py:2614} INFO - Dependencies all met for dep_context=non-requeueable deps ti=<TaskInstance: data_pipeline.run_tests manual__2025-03-03T01:53:22.667705+00:00 [queued]>
[2025-03-03T02:15:28.926+0000] {taskinstance.py:2614} INFO - Dependencies all met for dep_context=requeueable deps ti=<TaskInstance: data_pipeline.run_tests manual__2025-03-03T01:53:22.667705+00:00 [queued]>
[2025-03-03T02:15:28.927+0000] {taskinstance.py:2867} INFO - Starting attempt 1 of 2
[2025-03-03T02:15:28.957+0000] {taskinstance.py:2890} INFO - Executing <Task(PythonOperator): run_tests> on 2025-03-03 01:53:22.667705+00:00
[2025-03-03T02:15:28.967+0000] {standard_task_runner.py:72} INFO - Started process 555 to run task
[2025-03-03T02:15:28.973+0000] {standard_task_runner.py:104} INFO - Running: ['airflow', 'tasks', 'run', 'data_pipeline', 'run_tests', 'manual__2025-03-03T01:53:22.667705+00:00', '--job-id', '23', '--raw', '--subdir', 'DAGS_FOLDER/data_pipeline.py', '--cfg-path', '/tmp/tmppn79i3yv']
[2025-03-03T02:15:28.977+0000] {standard_task_runner.py:105} INFO - Job 23: Subtask run_tests
[2025-03-03T02:15:29.010+0000] {logging_mixin.py:190} WARNING - /home/airflow/.local/lib/python3.12/site-packages/airflow/settings.py:209 DeprecationWarning: The sql_alchemy_conn option in [core] has been moved to the sql_alchemy_conn option in [database] - the old setting has been used, but please update your config.
[2025-03-03T02:15:29.047+0000] {task_command.py:467} INFO - Running <TaskInstance: data_pipeline.run_tests manual__2025-03-03T01:53:22.667705+00:00 [running]> on host 71fb9604a64f
[2025-03-03T02:15:29.157+0000] {taskinstance.py:3134} INFO - Exporting env vars: AIRFLOW_CTX_DAG_OWNER='airflow' AIRFLOW_CTX_DAG_ID='data_pipeline' AIRFLOW_CTX_TASK_ID='run_tests' AIRFLOW_CTX_EXECUTION_DATE='2025-03-03T01:53:22.667705+00:00' AIRFLOW_CTX_TRY_NUMBER='1' AIRFLOW_CTX_DAG_RUN_ID='manual__2025-03-03T01:53:22.667705+00:00'
[2025-03-03T02:15:29.159+0000] {taskinstance.py:732} INFO - ::endgroup::
[2025-03-03T02:15:29.180+0000] {data_pipeline.py:74} INFO - Running unit tests...
[2025-03-03T02:15:31.229+0000] {data_pipeline.py:78} ERROR - Unit tests failed: Command '['pytest', '/opt/airflow/tests']' returned non-zero exit status 2.
[2025-03-03T02:15:31.231+0000] {python.py:240} INFO - Done. Returned value was: None
[2025-03-03T02:15:31.241+0000] {taskinstance.py:341} INFO - ::group::Post task execution logs
[2025-03-03T02:15:31.243+0000] {taskinstance.py:353} INFO - Marking task as SUCCESS. dag_id=data_pipeline, task_id=run_tests, run_id=manual__2025-03-03T01:53:22.667705+00:00, execution_date=20250303T015322, start_date=20250303T021528, end_date=20250303T021531
[2025-03-03T02:15:31.327+0000] {local_task_job_runner.py:266} INFO - Task exited with return code 0
[2025-03-03T02:15:31.349+0000] {taskinstance.py:3901} INFO - 0 downstream tasks scheduled from follow-on schedule check
[2025-03-03T02:15:31.351+0000] {local_task_job_runner.py:245} INFO - ::endgroup::
