[2025-04-17T07:40:06.417+0000] {local_task_job_runner.py:123} INFO - ::group::Pre task execution logs
[2025-04-17T07:40:06.445+0000] {taskinstance.py:2614} INFO - Dependencies all met for dep_context=non-requeueable deps ti=<TaskInstance: data_pipeline.clean_data scheduled__2025-04-17T06:00:00+00:00 [queued]>
[2025-04-17T07:40:06.464+0000] {taskinstance.py:2614} INFO - Dependencies all met for dep_context=requeueable deps ti=<TaskInstance: data_pipeline.clean_data scheduled__2025-04-17T06:00:00+00:00 [queued]>
[2025-04-17T07:40:06.465+0000] {taskinstance.py:2867} INFO - Starting attempt 1 of 2
[2025-04-17T07:40:06.497+0000] {taskinstance.py:2890} INFO - Executing <Task(PythonOperator): clean_data> on 2025-04-17 06:00:00+00:00
[2025-04-17T07:40:06.507+0000] {standard_task_runner.py:72} INFO - Started process 148 to run task
[2025-04-17T07:40:06.511+0000] {standard_task_runner.py:104} INFO - Running: ['airflow', 'tasks', 'run', 'data_pipeline', 'clean_data', 'scheduled__2025-04-17T06:00:00+00:00', '--job-id', '5', '--raw', '--subdir', 'DAGS_FOLDER/data_pipeline.py', '--cfg-path', '/tmp/tmpqzk95ifw']
[2025-04-17T07:40:06.514+0000] {standard_task_runner.py:105} INFO - Job 5: Subtask clean_data
[2025-04-17T07:40:06.543+0000] {logging_mixin.py:190} WARNING - /home/airflow/.local/lib/python3.12/site-packages/airflow/settings.py:209 DeprecationWarning: The sql_alchemy_conn option in [core] has been moved to the sql_alchemy_conn option in [database] - the old setting has been used, but please update your config.
[2025-04-17T07:40:06.594+0000] {task_command.py:467} INFO - Running <TaskInstance: data_pipeline.clean_data scheduled__2025-04-17T06:00:00+00:00 [running]> on host f2a4fe2704a3
[2025-04-17T07:40:06.599+0000] {logging_mixin.py:190} WARNING - /home/airflow/.local/lib/python3.12/site-packages/airflow/settings.py:470 DeprecationWarning: The sql_alchemy_conn option in [core] has been moved to the sql_alchemy_conn option in [database] - the old setting has been used, but please update your config.
[2025-04-17T07:40:06.748+0000] {taskinstance.py:3134} INFO - Exporting env vars: AIRFLOW_CTX_DAG_OWNER='airflow' AIRFLOW_CTX_DAG_ID='data_pipeline' AIRFLOW_CTX_TASK_ID='clean_data' AIRFLOW_CTX_EXECUTION_DATE='2025-04-17T06:00:00+00:00' AIRFLOW_CTX_TRY_NUMBER='1' AIRFLOW_CTX_DAG_RUN_ID='scheduled__2025-04-17T06:00:00+00:00'
[2025-04-17T07:40:06.750+0000] {taskinstance.py:732} INFO - ::endgroup::
[2025-04-17T07:40:06.806+0000] {data_pipeline.py:51} INFO - Executing script: /opt/airflow/scripts/data_preprocessing.py
[2025-04-17T07:42:38.817+0000] {local_task_job_runner.py:245} INFO - ::endgroup::
[2025-04-17T07:42:38.821+0000] {process_utils.py:132} INFO - Sending 15 to group 148. PIDs of all processes in the group: [150, 148]
[2025-04-17T07:42:38.822+0000] {process_utils.py:87} INFO - Sending the signal 15 to group 148
[2025-04-17T07:42:38.823+0000] {taskinstance.py:3094} ERROR - Received SIGTERM. Terminating subprocesses.
[2025-04-17T07:42:38.838+0000] {taskinstance.py:3095} ERROR - Stacktrace: 
  File "/home/airflow/.local/bin/airflow", line 8, in <module>
    sys.exit(main())
  File "/home/airflow/.local/lib/python3.12/site-packages/airflow/__main__.py", line 62, in main
    args.func(args)
  File "/home/airflow/.local/lib/python3.12/site-packages/airflow/cli/cli_config.py", line 49, in command
    return func(*args, **kwargs)
  File "/home/airflow/.local/lib/python3.12/site-packages/airflow/utils/cli.py", line 116, in wrapper
    return f(*args, **kwargs)
  File "/home/airflow/.local/lib/python3.12/site-packages/airflow/cli/commands/task_command.py", line 483, in task_run
    task_return_code = _run_task_by_selected_method(args, _dag, ti)
  File "/home/airflow/.local/lib/python3.12/site-packages/airflow/cli/commands/task_command.py", line 254, in _run_task_by_selected_method
    return _run_task_by_local_task_job(args, ti)
  File "/home/airflow/.local/lib/python3.12/site-packages/airflow/cli/commands/task_command.py", line 322, in _run_task_by_local_task_job
    ret = run_job(job=job_runner.job, execute_callable=job_runner._execute)
  File "/home/airflow/.local/lib/python3.12/site-packages/airflow/utils/session.py", line 97, in wrapper
    return func(*args, session=session, **kwargs)
  File "/home/airflow/.local/lib/python3.12/site-packages/airflow/jobs/job.py", line 421, in run_job
    return execute_job(job, execute_callable=execute_callable)
  File "/home/airflow/.local/lib/python3.12/site-packages/airflow/jobs/job.py", line 450, in execute_job
    ret = execute_callable()
  File "/home/airflow/.local/lib/python3.12/site-packages/airflow/jobs/local_task_job_runner.py", line 171, in _execute
    self.task_runner.start()
  File "/home/airflow/.local/lib/python3.12/site-packages/airflow/task/task_runner/standard_task_runner.py", line 55, in start
    self.process = self._start_by_fork()
  File "/home/airflow/.local/lib/python3.12/site-packages/airflow/task/task_runner/standard_task_runner.py", line 117, in _start_by_fork
    ret = args.func(args, dag=self.dag)
  File "/home/airflow/.local/lib/python3.12/site-packages/airflow/cli/cli_config.py", line 49, in command
    return func(*args, **kwargs)
  File "/home/airflow/.local/lib/python3.12/site-packages/airflow/utils/cli.py", line 116, in wrapper
    return f(*args, **kwargs)
  File "/home/airflow/.local/lib/python3.12/site-packages/airflow/cli/commands/task_command.py", line 483, in task_run
    task_return_code = _run_task_by_selected_method(args, _dag, ti)
  File "/home/airflow/.local/lib/python3.12/site-packages/airflow/cli/commands/task_command.py", line 256, in _run_task_by_selected_method
    return _run_raw_task(args, ti)
  File "/home/airflow/.local/lib/python3.12/site-packages/airflow/cli/commands/task_command.py", line 341, in _run_raw_task
    return ti._run_raw_task(
  File "/home/airflow/.local/lib/python3.12/site-packages/airflow/utils/session.py", line 97, in wrapper
    return func(*args, session=session, **kwargs)
  File "/home/airflow/.local/lib/python3.12/site-packages/airflow/models/taskinstance.py", line 3006, in _run_raw_task
    return _run_raw_task(
  File "/home/airflow/.local/lib/python3.12/site-packages/airflow/models/taskinstance.py", line 274, in _run_raw_task
    TaskInstance._execute_task_with_callbacks(
  File "/home/airflow/.local/lib/python3.12/site-packages/airflow/models/taskinstance.py", line 3161, in _execute_task_with_callbacks
    result = self._execute_task(context, task_orig)
  File "/home/airflow/.local/lib/python3.12/site-packages/airflow/models/taskinstance.py", line 3185, in _execute_task
    return _execute_task(self, context, task_orig)
  File "/home/airflow/.local/lib/python3.12/site-packages/airflow/models/taskinstance.py", line 768, in _execute_task
    result = _execute_callable(context=context, **execute_callable_kwargs)
  File "/home/airflow/.local/lib/python3.12/site-packages/airflow/models/taskinstance.py", line 734, in _execute_callable
    return ExecutionCallableRunner(
  File "/home/airflow/.local/lib/python3.12/site-packages/airflow/utils/operator_helpers.py", line 252, in run
    return self.func(*args, **kwargs)
  File "/home/airflow/.local/lib/python3.12/site-packages/airflow/models/baseoperator.py", line 424, in wrapper
    return func(self, *args, **kwargs)
  File "/home/airflow/.local/lib/python3.12/site-packages/airflow/operators/python.py", line 238, in execute
    return_value = self.execute_callable()
  File "/home/airflow/.local/lib/python3.12/site-packages/airflow/operators/python.py", line 256, in execute_callable
    return runner.run(*self.op_args, **self.op_kwargs)
  File "/home/airflow/.local/lib/python3.12/site-packages/airflow/utils/operator_helpers.py", line 252, in run
    return self.func(*args, **kwargs)
  File "/opt/airflow/dags/data_pipeline.py", line 52, in run_script
    subprocess.run(["python", script_path], check=True)
  File "/usr/local/lib/python3.12/subprocess.py", line 552, in run
    stdout, stderr = process.communicate(input, timeout=timeout)
  File "/usr/local/lib/python3.12/subprocess.py", line 1203, in communicate
    self.wait()
  File "/usr/local/lib/python3.12/subprocess.py", line 1266, in wait
    return self._wait(timeout=timeout)
  File "/usr/local/lib/python3.12/subprocess.py", line 2061, in _wait
    (pid, sts) = self._try_wait(0)
  File "/usr/local/lib/python3.12/subprocess.py", line 2019, in _try_wait
    (pid, sts) = os.waitpid(self.pid, wait_flags)
  File "/home/airflow/.local/lib/python3.12/site-packages/airflow/models/taskinstance.py", line 3095, in signal_handler
    self.log.error("Stacktrace: \n%s", "".join(traceback.format_stack()))

[2025-04-17T07:42:38.851+0000] {taskinstance.py:3313} ERROR - Task failed with exception
Traceback (most recent call last):
  File "/home/airflow/.local/lib/python3.12/site-packages/airflow/models/taskinstance.py", line 768, in _execute_task
    result = _execute_callable(context=context, **execute_callable_kwargs)
             ^^^^^^^^^^^^^^^^^^^^^^^^^^^^^^^^^^^^^^^^^^^^^^^^^^^^^^^^^^^^^
  File "/home/airflow/.local/lib/python3.12/site-packages/airflow/models/taskinstance.py", line 734, in _execute_callable
    return ExecutionCallableRunner(
           ^^^^^^^^^^^^^^^^^^^^^^^^
  File "/home/airflow/.local/lib/python3.12/site-packages/airflow/utils/operator_helpers.py", line 252, in run
    return self.func(*args, **kwargs)
           ^^^^^^^^^^^^^^^^^^^^^^^^^^
  File "/home/airflow/.local/lib/python3.12/site-packages/airflow/models/baseoperator.py", line 424, in wrapper
    return func(self, *args, **kwargs)
           ^^^^^^^^^^^^^^^^^^^^^^^^^^^
  File "/home/airflow/.local/lib/python3.12/site-packages/airflow/operators/python.py", line 238, in execute
    return_value = self.execute_callable()
                   ^^^^^^^^^^^^^^^^^^^^^^^
  File "/home/airflow/.local/lib/python3.12/site-packages/airflow/operators/python.py", line 256, in execute_callable
    return runner.run(*self.op_args, **self.op_kwargs)
           ^^^^^^^^^^^^^^^^^^^^^^^^^^^^^^^^^^^^^^^^^^^
  File "/home/airflow/.local/lib/python3.12/site-packages/airflow/utils/operator_helpers.py", line 252, in run
    return self.func(*args, **kwargs)
           ^^^^^^^^^^^^^^^^^^^^^^^^^^
  File "/opt/airflow/dags/data_pipeline.py", line 52, in run_script
    subprocess.run(["python", script_path], check=True)
  File "/usr/local/lib/python3.12/subprocess.py", line 552, in run
    stdout, stderr = process.communicate(input, timeout=timeout)
                     ^^^^^^^^^^^^^^^^^^^^^^^^^^^^^^^^^^^^^^^^^^^
  File "/usr/local/lib/python3.12/subprocess.py", line 1203, in communicate
    self.wait()
  File "/usr/local/lib/python3.12/subprocess.py", line 1266, in wait
    return self._wait(timeout=timeout)
           ^^^^^^^^^^^^^^^^^^^^^^^^^^^
  File "/usr/local/lib/python3.12/subprocess.py", line 2061, in _wait
    (pid, sts) = self._try_wait(0)
                 ^^^^^^^^^^^^^^^^^
  File "/usr/local/lib/python3.12/subprocess.py", line 2019, in _try_wait
    (pid, sts) = os.waitpid(self.pid, wait_flags)
                 ^^^^^^^^^^^^^^^^^^^^^^^^^^^^^^^^
  File "/home/airflow/.local/lib/python3.12/site-packages/airflow/models/taskinstance.py", line 3097, in signal_handler
    raise AirflowTaskTerminated("Task received SIGTERM signal")
airflow.exceptions.AirflowTaskTerminated: Task received SIGTERM signal
[2025-04-17T07:42:38.865+0000] {taskinstance.py:1226} INFO - Marking task as UP_FOR_RETRY. dag_id=data_pipeline, task_id=clean_data, run_id=scheduled__2025-04-17T06:00:00+00:00, execution_date=20250417T060000, start_date=20250417T074006, end_date=20250417T074238
[2025-04-17T07:42:38.892+0000] {taskinstance.py:341} INFO - ::group::Post task execution logs
[2025-04-17T07:42:38.916+0000] {process_utils.py:80} INFO - Process psutil.Process(pid=148, status='terminated', exitcode=2, started='07:40:05') (148) terminated with exit code 2
[2025-04-17T07:42:38.918+0000] {process_utils.py:80} INFO - Process psutil.Process(pid=150, status='terminated', started='07:40:06') (150) terminated with exit code None
[2025-04-17T07:42:55.026+0000] {local_task_job_runner.py:123} INFO - ::group::Pre task execution logs
[2025-04-17T07:42:55.037+0000] {taskinstance.py:2604} INFO - Dependencies not met for <TaskInstance: data_pipeline.clean_data scheduled__2025-04-17T06:00:00+00:00 [up_for_retry]>, dependency 'Not In Retry Period' FAILED: Task is not ready for retry yet but will be retried automatically. Current date is 2025-04-17T07:42:55.036911+00:00 and task will be retried at 2025-04-17T07:47:38.864280+00:00.
[2025-04-17T07:42:55.049+0000] {local_task_job_runner.py:166} INFO - Task is not able to be run
